Workbook

Sheet Смета
A1: Смета материалов под ключ — без работ
A2: Не входит: окна, двери, утепление и плёнка нар. стен / пола / потолка, каркасы перегородок, вся терраса. Цены ориентир (Петрович СПб / Valtec), сентябрь 2026. Меняйте столбец «Цена» — сумма пересчитается.
A4: № | B4: Раздел / материал | C4: Ед. | D4: Кол-во | E4: Цена, ₽ | F4: Сумма, ₽ | G4: Источник кол-ва | H4: Артикул / типоразмер | I4: Примечание
A5: 1. Перегородки — вата в каркас; лист только в с/у (каркас уже стоит)
A6: 1.1 | B6: Минвата / акустические плиты 100 мм в перегородки | C6: м² | D6: 50 | E6: 280 | F6: =IF(D6="","",D6*E6) | G6: перегородки ≈ 44 м² + запас | H6: плита 600×1200×100 | I6: звук между комнатами; лист с жилой стороны не кладём
A7: 1.2 | B7: ГВЛВ 12.5 мм в с/у (стены + потолок) | C7: лист | D7: 8 | E7: 890 | F7: =IF(D7="","",D7*E7) | G7: вкладка С_у | H7: 1200×2500 влагостойкий | I7: под плитку и краску потолка; жилые перегородки без ГВЛ
A8: 1.3 | B8: Саморезы, лента, шпаклёвка швов — только с/у | C8: компл | D8: 1 | E8: 2200 | F8: =IF(D8="","",D8*E8) | G8: норма на мокрую зону | H8: Кнауф / аналог | I8: не на весь дом: МДФ идёт по обрешётке на стойки
A9: 1.4 | B9: Лента уплотнительная и демпфер к перегородкам | C9: м.п. | D9: 40 | E9: 45 | F9: =IF(D9="","",D9*E9) | G9: периметр примыканий | H9: поролон / Дихтунгсбанд
B10: Итого по разделу | F10: =SUM(F6:F9)
A12: 2. Обрешётка и МДФ-панели жилых стен и скатных потолков (с/у и терраса нет)
A13: 2.1 | B13: Панель МДФ Союз Классик дуб альпийский 2600×238×6 | C13: шт | D13: =Обшивка!B9 | E13: 260 | F13: =IF(D13="","",D13*E13) | G13: вкладка Обшивка | H13: раб. 0,572 м², уп. 8 шт | I13: ориентир 260 ₽/шт; Петрович продаёт поштучно, кратно 8
A14: 2.2 | B14: Брусок 20×40×3000 сухой (обрешётка) | C14: шт | D14: =Обшивка!B12 | E14: 95 | F14: =IF(D14="","",D14*E14) | G14: вкладка Обшивка | H14: шаг 400 мм | I14: по плёнке нар. стен и по листам перегородок
A15: 2.3 | B15: Кляймер №3 с гвоздями (под 6 мм) | C15: упак 100 шт | D15: =CEILING(Обшивка!B13/100,1) | E15: 71 | F15: =IF(D15="","",D15*E15) | G15: ≈8 шт на панель | H15: кляймер под 6 мм
A16: 2.4 | B16: Саморезы 3.5×35 / скобы степлера 6–8 мм | C16: компл | D16: 1 | E16: 2200 | F16: =IF(D16="","",D16*E16) | G16: обрешётка + панели | I16: производитель запрещает жидкие гвозди
A17: 2.5 | B17: Угол МДФ универсальный 2600, дуб альпийский | C17: шт | D17: 16 | E17: 190 | F17: =IF(D17="","",D17*E17) | G17: внутренние/наружные углы | H17: Союз в цвет панелей
A18: 2.6 | B18: Галтель / потолочный плинтус МДФ 2600 в цвет | C18: шт | D18: 22 | E18: 170 | F18: =IF(D18="","",D18*E18) | G18: периметр жилых + конёк | H18: закрывает стык панели 2,60 и стену 2,615
A19: 2.7 | B19: Плинтус напольный МДФ 60–80 мм + уголки, в цвет | C19: м.п. | D19: =Обшивка!B14 | E19: 290 | F19: =IF(D19="","",D19*E19) | G19: периметр жилых − двери | I19: с/у — плинтус керамический в плитке
A20: 2.8 | B20: Нащельник у окон/дверей, расходники | C20: компл | D20: 1 | E20: 3500 | F20: =IF(D20="","",D20*E20) | I20: изделия окон и дверей свои, только примыкание
B21: Итого по разделу | F21: =SUM(F13:F20)
A23: 3. Тёплый пол сухой по всему дому (пол уже утеплён и под плёнкой)
A24: 3.1 | B24: Теплораспределительная пластина VALTEC VT.FP.SZ | C24: шт | D24: =Теплый_пол!B12 | E24: 339 | F24: =IF(D24="","",D24*E24) | G24: вкладка Теплый_пол | H24: VT.FP.SZ.0125 1000×125 | I24: кратно 40 шт, шаг 125 мм
A25: 3.2 | B25: Труба PEX-a / PERT 16×2 для ТП | C25: м | D25: =Теплый_пол!B14 | E25: 82 | F25: =IF(D25="","",D25*E25) | G25: ≈8 м/м² + 10% | H25: бухта 200 м ×2 | I25: 5–6 контуров до 80 м
A26: 3.3 | B26: Коллектор в сборе с расходомерами, 7 выходов | C26: шт | D26: 1 | E26: 18900 | F26: =IF(D26="","",D26*E26) | G26: Теплый_пол!B15 | H26: Valtec / Uponor аналог | I26: по числу контуров
A27: 3.4 | B27: Шкаф коллекторный встраиваемый | C27: шт | D27: 1 | E27: 4200 | F27: =IF(D27="","",D27*E27) | H27: 600–800 мм | I27: в холле / кухне
A28: 3.5 | B28: Насосно-смесительный узел для ТП | C28: шт | D28: 1 | E28: 18900 | F28: =IF(D28="","",D28*E28) | H28: Valtec Combi / аналог | I28: если котёл без своей погоды
A29: 3.6 | B29: Евроконус 16×3/4, соединители, отводы | C29: компл | D29: 1 | E29: 5200 | F29: =IF(D29="","",D29*E29) | G29: на 7 петель
A30: 3.7 | B30: Демпферная лента 8–10 мм | C30: м.п. | D30: 50 | E30: 35 | F30: =IF(D30="","",D30*E30) | G30: периметр комнат | I30: уже есть плёнка пола — лента к стенам
A31: 3.8 | B31: Скотч алюминиевый / фольгированный | C31: шт | D31: 4 | E31: 320 | F31: =IF(D31="","",D31*E31) | H31: 50 м | I31: стыки плёнки при монтаже пластин
B32: Итого по разделу | F32: =SUM(F24:F31)
A34: 4. Основание пола и финиш (ламинат не на пластины ТП)
A35: 4.1 | B35: OSB-3 22 мм — черновой настил по лагам | C35: лист 2500×1250 | D35: =CEILING(Полы!B10*1.08/3.125,1) | E35: 2150 | F35: =IF(D35="","",D35*E35) | G35: весь отапливаемый пол +8% | H35: 3.125 м²/лист | I35: обнулить, если черновой пол уже есть; плёнка сама по себе не основание
A36: 4.2 | B36: Саморезы 4.2×65 к лагам | C36: упак 200 шт | D36: 4 | E36: 450 | F36: =IF(D36="","",D36*E36) | G36: черновой настил 22 мм
A37: 4.3 | B37: OSB-3 12 мм поверх пластин ТП — под ламинат | C37: лист 2500×1250 | D37: =CEILING((Полы!G5+Полы!G6+Полы!G7+Полы!G8)/3.125,1) | E37: 1250 | F37: =IF(D37="","",D37*E37) | G37: жилые с запасом | H37: 3.125 м²/лист | I37: на этот слой: подложка 1–2 мм и ламинат; фанера не закладывается
A38: 4.4 | B38: ГВЛВ 10 мм, 2 слоя — пол с/у поверх ТП | C38: лист 1200×2500 | D38: 4 | E38: 890 | F38: =IF(D38="","",D38*E38) | G38: 3.59 м² ×2 слоя + запас | H38: 3.0 м²/лист | I38: под гидроизоляцию и плитку
A39: 4.5 | B39: Саморезы 3.5×41 + клей по дереву на OSB 12 мм | C39: компл | D39: 1 | E39: 2800 | F39: =IF(D39="","",D39*E39) | G39: OSB жилых + ГВЛВ с/у | I39: листы вразбежку, не крутить в трубу
A40: 4.6 | B40: Ламинат 33 кл. / SPC для тёплого пола | C40: м² | D40: =Полы!G5+Полы!G6+Полы!G7+Полы!G8 | E40: 1290 | F40: =IF(D40="","",D40*E40) | G40: вкладка Полы, с запасом | H40: 8–10 мм, допуск на ТП | I40: класть на OSB 12 мм, не на пластины
A41: 4.7 | B41: Подложка под ламинат для ТП (тонкая 1–2 мм) | C41: м² | D41: =Полы!G5+Полы!G6+Полы!G7+Полы!G8 | E41: 180 | F41: =IF(D41="","",D41*E41) | G41: вкладка Полы | H41: не фольгированная толстая | I41: не режет тепло
A42: 4.8 | B42: Пороги / стык ламинат–плитка | C42: шт | D42: 2 | E42: 650 | F42: =IF(D42="","",D42*E42) | G42: с/у и вход | H42: алюминий / Т-профиль
B43: Итого по разделу | F43: =SUM(F35:F42)
A45: 5. Санузел — гидроизоляция, плитка, потолок (МДФ нет)
...

Sheet Сводка
A1: Сводка сметы по видам работ
A2: Только материалы. Суммы = итоги разделов вкладки Смета.
A4: № | B4: Раздел | C4: Сумма, ₽ | D4: Доля
A5: 1 | B5: 1. Перегородки — вата + ГВЛВ с/у | C5: =Смета!F10 | D5: =IF($C$16=0,0,C5/$C$16)
A6: 2 | B6: 2. МДФ-панели и обрешётка | C6: =Смета!F21 | D6: =IF($C$16=0,0,C6/$C$16)
A7: 3 | B7: 3. Тёплый пол сухой | C7: =Смета!F32 | D7: =IF($C$16=0,0,C7/$C$16)
A8: 4 | B8: 4. Настил пола и ламинат | C8: =Смета!F43 | D8: =IF($C$16=0,0,C8/$C$16)
A9: 5 | B9: 5. Санузел (плитка, гидроизоляция) | C9: =Смета!F54 | D9: =IF($C$16=0,0,C9/$C$16)
A10: 6 | B10: 6. Сантехника — приборы | C10: =Смета!F64 | D10: =IF($C$16=0,0,C10/$C$16)
A11: 7 | B11: 7. Источник тепла | C11: =Смета!F72 | D11: =IF($C$16=0,0,C11/$C$16)
A12: 8 | B12: 8. Водопровод и канализация | C12: =Смета!F80 | D12: =IF($C$16=0,0,C12/$C$16)
A13: 9 | B13: 9. Электрика и вентиляция с/у | C13: =Смета!F97 | D13: =IF($C$16=0,0,C13/$C$16)
A14: 10 | B14: 10. Прочее и расходники | C14: =Смета!F104 | D14: =IF($C$16=0,0,C14/$C$16)
B16: Итого материалы | C16: =Смета!F106 | D16: =SUM(D5:D14)
A18: Не входит в итог: работы; окна; двери; утеплитель и плёнка наружных стен, пола и потолка; каркасы перегородок; терраса; кухня (гарнитур, мойка, плита, вытяжка). Ламинат кладётся на OSB-3 12 мм поверх пластин ТП, не на пластины. Фанеры нет.

Sheet Исходные
A1: Барнхаус 10.5×6 — исходные данные
A2: Отапливаемый контур А–Г. Терраса Г–Д в расчёты отделки не входит. Цены — ориентир Петрович/Valtec, сентябрь 2026, без работ.
A4: Параметр | B4: Значение | C4: Ед. | D4: Комментарий
A5: Габарит наружный с террасой | B5: 10.5 | C5: м | D5: оси А–Д × 6.0 м
A6: Отапливаемая длина А–Г | B6: 8.95 | C6: м | D6: без террасы 1.55 м
A7: Ширина наружная | B7: 6 | C7: м
A8: Ширина внутренняя | B8: 5.5 | C8: м | D8: стены 250 мм
A9: Длина внутренняя А–Г | B9: 8.45 | C9: м
A10: Высота карниза | B10: 2.615 | C10: м | D10: от чистого пола
A11: Высота конька (кровля) | B11: 4.042 | C11: м | D11: по фасаду
A12: Высота конька внутри | B12: 3.897 | C12: м | D12: 2.615 + 2.75·tg25°
A13: Уклон кровли | B13: 25 | C13: ° | D13: двускатная, конёк вдоль длинной оси
A14: Площадь пола отапливаемая | B14: 45.31 | C14: м² | D14: по ведомости помещений
A15: Площадь жилых комнат (без с/у) | B15: 41.72 | C15: м² | D15: под МДФ-панели
A16: Площадь с/у | B16: 3.59 | C16: м² | D16: плитка
A17: Терраса — не считаем | B17: 9.12 | C17: м² | D17: не трогаем
A18: Толщина нар. стен | B18: 0.25 | C18: м | D18: уже утеплены + плёнка
A19: Толщина перегородок | B19: 0.11 | C19: м | D19: каркасы стоят
A21: Что уже есть — в смету НЕ входит
A22: Окна (ОК-1, ОК-1а, ОК-2, ОК-3, ОК-3а, ОК-4, ОК-5, ОК-6) — установлены
A23: Двери: входная ДН-4 стекло и внутренние ДВ-1, ДВ-2, ДВ-3 — установлены
A24: Все наружные стены утеплены и зашиты пароизоляционной плёнкой
A25: Полы утеплены и зашиты плёнкой
A26: Потолки (скаты) утеплены и зашиты плёнкой
A27: Каркасы внутренних перегородок стоят
A28: Терраса — не трогаем (ни пол, ни стены, ни кровля, ни ограждение)
A30: Что считаем в смете (материалы, без работ)
A31: Заполнение перегородок минватой; МДФ сразу на обрешётку каркаса. ГВЛВ только в с/у под плитку
A32: Обрешётка + МДФ-панели дуб альпийский 2600×238×6 по жилым стенам и скатным потолкам (без с/у)
A33: Сухой тёплый пол VT.FP.SZ по всему отапливаемому дому, включая с/у
... A39: Плинтус и уголки в цвет МДФ, расходники (панели уже с покрытием, лак не нужен)

Sheet Комнаты
A1: Ведомость помещений
A2: Площади пола по чертежу. Потолок скатный = пол / cos25°.
A4: Помещение | B4: Тип | C4: Пол, м² | D4: Потолок скатный, м² | E4: Тёплый пол | F4: Финиш стен / потолка
A5: Спальня 1 | B5: жилая | C5: 9.21 | D5: =C5/COS(RADIANS(25)) | E5: да | F5: МДФ дуб альпийский / МДФ
A6: Спальня 2 | B6: жилая | C6: 9.21 | D6: =C6/COS(RADIANS(25)) | E6: да | F6: МДФ дуб альпийский / МДФ
A7: Кухня-гостиная | B7: жилая | C7: 20.29 | D7: =C7/COS(RADIANS(25)) | E7: да | F7: МДФ дуб альпийский / МДФ
A8: Прихожая | B8: жилая | C8: 3.01 | D8: =C8/COS(RADIANS(25)) | E8: да | F8: МДФ дуб альпийский / МДФ
A9: С/у | B9: мокрый | C9: 3.59 | D9: =C9/COS(RADIANS(25)) | E9: да | F9: плитка / влагостойкий потолок
A10: Терраса | B10: улица | C10: 9.12 | D10: — | E10: нет / не трогаем | F10: не трогаем
A11: Итого отапливаемые | C11: =SUM(C5:C9) | D11: =SUM(D5:D9)
A13: Примечание
A14: Площади пола — из ведомости помещений чертежа (сумма 45.31 м²). Потолок барнхауса двускатный 25°: площадь потолка = площадь пола / cos25° ≈ ×1.103. Терраса 9.12 м² в отделку и тёплый пол не входит.

Sheet Полы
A1: Полы — площади и пирог
A2: Утеплитель и плёнка уже лежат. Ламинат не на пластины: нужен сплошной настил.
A4: Помещение | B4: Площадь, м² | C4: Отопление пола | D4: Шаг трубы, мм | E4: Финиш | F4: Запас финиша, % | G4: К закупке, м²
A5: Спальня 1 | B5: 9.21 | C5: да | D5: 125 | E5: ламинат 33 кл. / SPC на ТП | F5: 10 | G5: =B5*(1+F5/100)
A6: Спальня 2 | B6: 9.21 | C6: да | D6: 125 | E6: ламинат 33 кл. / SPC на ТП | F6: 10 | G6: =B6*(1+F6/100)
A7: Кухня-гостиная | B7: 20.29 | C7: да | D7: 125 | E7: ламинат 33 кл. / SPC на ТП | F7: 10 | G7: =B7*(1+F7/100)
A8: Прихожая | B8: 3.01 | C8: да | D8: 125 | E8: ламинат 33 кл. / SPC на ТП | F8: 10 | G8: =B8*(1+F8/100)
A9: С/у | B9: 3.59 | C9: да | D9: 125 | E9: плитка керамогранит | F9: 12 | G9: =B9*(1+F9/100)
A10: Итого отапливаемые полы | B10: =SUM(B5:B9) | G10: =SUM(G5:G9)
A12: Ламинат / SPC (жилые) | B12: =G5+G6+G7+G8
A13: Плитка пола с/у | B13: =G9
A15: Пирог дальше уже сделанного (лаги + утеплитель + плёнка): 1) Черновой настил OSB-3 22 мм по лагам — если под плёнкой ещё дырки между лагами. Если черновой пол уже лежит — эту строку в смете обнулить. 2) Пластины VT.FP.SZ + труба 16 мм (вкладка Теплый_пол). 3) Второй слой OSB-3 12 мм поверх пластин в жилых — на НЕГО кладётся тонкая подложка и ламинат. Фанера не нужна: OSB дешевле и тот же сплошной щит. Прямо на пластины ламинат нельзя. 4) В с/у поверх труб — 2 слоя ГВЛВ 10 мм, затем гидроизоляция и плитка. 5) Подложка под ламинат только 1–2 мм «для ТП», без толстой пробки.

Sheet Стены
A1: Стены — развёртка внутренних поверхностей
A2: Нар. стены уже с плёнкой: только отделка. Перегородки: каркас стоит, нужны заполнение, обшивка и отделка. Проёмы вычтены.
A4: Участок | B4: Конструкция | C4: Зона | D4: Грязная площадь, м² | E4: Проёмы, м² | F4: К отделке, м² | G4: Отделка | H4: Примечание
A5: Север, спальни, внутреннее лицо фронтона | B5: нар. стена | C5: жилая | D5: 17.909 | E5: 5.04 | F5: =D5-E5 | G5: МДФ | H5: минус два ОК-4
A6: Юг, гостиная/холл, внутреннее лицо фронтона | B6: нар. стена | C6: жилая | D6: 17.909 | E6: 14.471 | F6: =D6-E6 | G6: МДФ | H6: минус остекление торца и ДН-4
A7: Восток, длинная стена | B7: нар. стена | C7: жилая | D7: 22.097 | E7: 0 | F7: =D7-E7 | G7: МДФ | H7: высота карниза 2.615
A8: Запад, спальня 1 | B8: нар. стена | C8: жилая | D8: 8.937 | E8: 0 | F8: =D8-E8 | G8: МДФ
A9: Запад, гостиная | B9: нар. стена | C9: жилая | D9: 5.472 | E9: 0 | F9: =D9-E9 | G9: МДФ | H9: южнее с/у
A10: Перегородка спален, обе стороны | B10: перегородка | C10: жилая | D10: 26.638 | E10: 0 | F10: =D10-E10 | G10: МДФ | H10: по коньку, h≈3.90
A11: Перегородка спальни/зал, сторона спален | B11: перегородка | C11: жилая | D11: 17.909 | E11: 3.36 | F11: =D11-E11 | G11: МДФ | H11: минус ДВ-2, ДВ-3
A12: Перегородка спальни/зал, сторона зала | B12: перегородка | C12: жилая | D12: 14.051 | E12: 3.36 | F12: =D12-E12 | G12: МДФ | H12: без участка с/у
A13: Стенка с/у, сторона зала | B13: перегородка | C13: жилая | D13: 8.787 | E13: 1.47 | F13: =D13-E13 | G13: МДФ | H13: минус ДВ-1
A14: Стенка с/у, сторона кухни | B14: перегородка | C14: жилая | D14: 3.858 | E14: 0 | F14: =D14-E14 | G14: МДФ
A15: С/у запад (карниз) | B15: нар. стена | C15: мокрый | D15: 7.113 | E15: 0.49 | F15: =D15-E15 | G15: плитка | H15: минус ОК-2
A16: С/у восток | B16: перегородка | C16: мокрый | D16: 8.787 | E16: 1.47 | F16: =D16-E16 | G16: плитка | H16: минус ДВ-1
A17: С/у север | B17: перегородка | C17: мокрый | D17: 3.858 | E17: 0 | F17: =D17-E17 | G17: плитка
A18: С/у юг | B18: перегородка | C18: мокрый | D18: 3.858 | E18: 0 | F18: =D18-E18 | G18: плитка
A19: Итого все стены | D19: =SUM(D5:D18) | E19: =SUM(E5:E18) | F19: =SUM(F5:F18)
A20: из них МДФ (жилые) | F20: =SUMIF(C5:C18,"жилая",F5:F18)
A21: из них плитка (с/у внутри) | F21: =SUMIF(C5:C18,"мокрый",F5:F18)
A22: перегородки, обе стороны (под обшивку листа) | F22: =SUMIF(B5:B18,"перегородка",D5:D18)
A24: Высоты: длинные стены 2.615 м; фронтоны и поперечные перегородки — по скату (карниз 2.615, конёк внутри 3.897 м). Площадь фронтона = интеграл высоты по ширине 5.50 м.

Sheet Потолки
A1: Потолки скатные
A2: Утеплитель и плёнка уже есть. Считаем обрешётку и обшивку.
A4: Помещение | B4: Пол, м² | C4: Коэффициент ската | D4: Потолок, м² | E4: Отделка | F4: Примечание
A5: Спальня 1 | B5: 9.21 | C5: =1/COS(RADIANS(25)) | D5: =B5*C5 | E5: МДФ дуб альпийский | F5: Sпот = Sпол / cos25°
A6: Спальня 2 | B6: 9.21 | C6: =1/COS(RADIANS(25)) | D6: =B6*C6 | E6: МДФ дуб альпийский | F6: Sпот = Sпол / cos25°
A7: Кухня-гостиная | B7: 20.29 | C7: =1/COS(RADIANS(25)) | D7: =B7*C7 | E7: МДФ дуб альпийский | F7: Sпот = Sпол / cos25°
A8: Прихожая | B8: 3.01 | C8: =1/COS(RADIANS(25)) | D8: =B8*C8 | E8: МДФ дуб альпийский | F8: Sпот = Sпол / cos25°
A9: С/у | B9: 3.59 | C9: =1/COS(RADIANS(25)) | D9: =B9*C9 | E9: ГВЛВ + краска влагостойкая | F9: Sпот = Sпол / cos25°
A10: Итого | B10: =SUM(B5:B9) | D10: =SUM(D5:D9)
A11: МДФ (без с/у) | D11: =SUM(D5:D8)
A12: с/у потолок | D12: =D9

Sheet Окна
A1: Окна — ведомость (закупка не нужна)
A2: Изделия уже стоят. Площадь для справки и для вычета из стен.
A4: Марка | B4: Где | C4: Ширина, м | D4: Высота, м | E4: Sill, м | F4: Кол-во | G4: Площадь, м² | H4: Статус
A5: ОК-4 | B5: север, спальня 1 | C5: 1.2 | D5: 2.1 | E5: 0.029 | F5: 1 | G5: =C5*D5*F5 | H5: есть, не покупать
A6: ОК-4 | B6: север, спальня 2 | C6: 1.2 | D6: 2.1 | E6: 0.029 | F6: 1 | G6: =C6*D6*F6 | H6: есть, не покупать
A7: ОК-2 | B7: запад, с/у | C7: 0.7 | D7: 0.7 | E7: 1.1 | F7: 1 | G7: =C7*D7*F7 | H7: есть, не покупать
A8: ОК-6 | B8: юг, гостиная, низ | C8: 1.2 | D8: 2 | E8: 0 | F8: 1 | G8: =C8*D8*F8 | H8: есть, не покупать
A9: ОК-5 | B9: юг, гостиная, низ | C9: 1.3 | D9: 2 | E9: 0 | F9: 1 | G9: =C9*D9*F9 | H9: есть, не покупать
A10: ОК-5 | B10: юг, холл, низ | C10: 1.4 | D10: 2 | E10: 0 | F10: 1 | G10: =C10*D10*F10 | H10: есть, не покупать
A11: ОК-1 | B11: юг, второй свет над дверью | C11: 1 | D11: 0.6 | E11: 2.2 | F11: 1 | G11: =C11*D11*F11 | H11: есть, не покупать
A12: ОК-3а | B12: юг, второй свет | C12: 1.4 | D12: 1.2 | E12: 2.2 | F12: 1 | G12: =C12*D12*F12 | H12: есть, не покупать
A13: ОК-3 | B13: юг, второй свет | C13: 1.3 | D13: 1.37 | E13: 2.2 | F13: 1 | G13: =C13*D13*F13 | H13: есть, не покупать
A14: ОК-1а | B14: юг, второй свет | C14: 1.2 | D14: 0.55 | E14: 2.2 | F14: 1 | G14: =C14*D14*F14 | H14: есть, не покупать
A15: Итого остекление окон | G15: =SUM(G5:G14)
A16: ДН-4 стекло (дверь, см. вкладку Двери) | G16: 1.95
A17: Всего светопрозрачных (окна+ДН-4) | G17: =G15+G16

Sheet Двери
A1: Двери — ведомость (закупка не нужна)
A2: Полотно, коробка и фурнитура уже есть. Наличники в смету не ставил.
A4: Марка | B4: Тип | C4: Где | D4: Ширина, м | E4: Высота, м | F4: Материал | G4: Площадь, м² | H4: Статус
A5: ДН-4 | B5: входная | C5: торец у террасы, холл | D5: 1 | E5: 1.95 | F5: стекло | G5: =D5*E5 | H5: есть, не покупать
A6: ДВ-1 | B6: межкомнатная | C6: зал → с/у | D6: 0.7 | E6: 2.1 | F6: глухая | G6: =D6*E6 | H6: есть, не покупать
A7: ДВ-2 | B7: межкомнатная | C7: зал → спальня 2 | D7: 0.8 | E7: 2.1 | F7: глухая | G7: =D7*E7 | H7: есть, не покупать
A8: ДВ-3 | B8: межкомнатная | C8: зал → спальня 1 | D8: 0.8 | E8: 2.1 | F8: глухая | G8: =D8*E8 | H8: есть, не покупать
A9: Итого проёмы дверей | G9: =SUM(G5:G8)

Sheet Обшивка
A1: Обшивка МДФ-панелями — расчёт
A2: Жилые стены + скатные потолки. С/у и терраса исключены. Панель Союз 2600×238×6, рабочая ширина 220 мм.
A4: Показатель | B4: Значение | C4: Ед. | D4: Формула / источник | E4: Запас | F4: К закупке
A5: Стены под МДФ | B5: =SUMIF(Стены!C5:C18,"жилая",Стены!F5:F18) | C5: м² | D5: Стены! жилая | E5: 0.1 | F5: =B5*(1+E5)
A6: Потолки под МДФ | B6: =Потолки!D11 | C6: м² | D6: Потолки! без с/у | E6: 0.15 | F6: =B6*(1+E6)
A7: Итого поверхность МДФ | B7: =B5+B6 | C7: м² | D7: стены+потолки | F7: =F5+F6
A8: Рабочая площадь 1 панели | B8: 0.572 | C8: м²/шт | D8: 2.600 × 0.220 (шип не в покрытии)
A9: Панелей, кратно упаковке 8 шт | B9: =CEILING(F7/B8/8,1)*8 | C9: шт | D9: CEILING(запас / 0.572 / 8)×8 | F9: =B9
A10: Упаковок ×8 | B10: =B9/8 | C10: уп | D10: панели / 8 | F10: =B10
A11: Обрешётка 20×40 шаг 400 мм | B11: =B7/0.4*1.15 | C11: м.п. | D11: S / 0.40 × 1.15 | F11: =B11
A12: Брусок 20×40×3000 | B12: =CEILING(B11/3,1) | C12: шт | D12: м.п. / 3 | F12: =B12
A13: Кляймер №3 (под 6 мм) | B13: =B9*8 | C13: шт | D13: ≈8 шт на панель 2.6 м | F13: =B13
A14: Плинтус жилые | B14: 51 | C14: м.п. | D14: периметр комнат − двери ×1.10 | F14: 51
A15: Угол / галтель МДФ 2600 в цвет | B15: 42 | C15: шт | D15: углы + конёк + потолочный периметр / 2.6 | F15: 42
A17: МДФ Союз Классик дуб альпийский 2600×238×6 мм. Полная площадь листа 0,619 м², в покрытие идёт рабочая ширина 220 мм → 0,572 м²/шт. Упаковка 8 шт (Петрович продаёт поштучно, закладываю кратно упаковке). Панель 2,60 м на стену 2,615 м: низ/верх закрывает плинтус и галтель. На скатах уклон 3,03 м > 2,60 м — стык и косые резы, запас потолка 15%. Покрытие уже есть, лак/масло не нужны. В с/у и на террасу не кладём (влажность / не трогаем).

Sheet Теплый_пол
A1: Тёплый пол сухой VALTEC VT.FP.SZ
A2: По всему отапливаемому дому, включая с/у. Терраса нет.
A4: Помещение | B4: Пол, м² | C4: Норма, шт/м² | D4: Пластины, шт | E4: Труба 16 мм, м | F4: Контуры | G4: Примечание
A5: Спальня 1 | B5: 9.21 | C5: 6.4 | D5: =CEILING(B5*C5,1) | E5: =B5*8 | F5: =CEILING(E5/80,1) | G5: шаг 125 мм, пластины на прямых
A6: Спальня 2 | B6: 9.21 | C6: 6.4 | D6: =CEILING(B6*C6,1) | E6: =B6*8 | F6: =CEILING(E6/80,1) | G6: шаг 125 мм, пластины на прямых
A7: Кухня-гостиная | B7: 20.29 | C7: 6.4 | D7: =CEILING(B7*C7,1) | E7: =B7*8 | F7: =CEILING(E7/80,1) | G7: шаг 125 мм, пластины на прямых
A8: Прихожая | B8: 3.01 | C8: 6.4 | D8: =CEILING(B8*C8,1) | E8: =B8*8 | F8: =CEILING(E8/80,1) | G8: шаг 125 мм, пластины на прямых
A9: С/у | B9: 3.59 | C9: 6.4 | D9: =CEILING(B9*C9,1) | E9: =B9*8 | F9: =CEILING(E9/80,1) | G9: шаг 125 мм, пластины на прямых
A10: Итого | B10: =SUM(B5:B9) | D10: =SUM(D5:D9) | E10: =SUM(E5:E9) | F10: =SUM(F5:F9)
A12: К закупке пластин (кратно 40) | B12: =CEILING(D10/40,1)*40
A13: Коробок ×40 | B13: =B12/40
A14: Труба 16 мм с запасом 10% | B14: =CEILING(E10*1.1,10)
A15: Коллектор, выходов | B15: =MAX(F10,5)
A17: Пластина VT.FP.SZ.0125 = 1000×125 мм, труба Ø16. Пачка 40 шт. Норма 6.4 шт/м² ≈ 80% покрытия (на петлях пластин нет). Контур не длиннее 80–90 м — отсюда число петель. Пол уже утеплён и под плёнкой: подложку под пластины не закладывал. Сверху на пластины — OSB-3 12 мм (жилые) / ГВЛВ (с/у), затем финиш. Не класть ламинат на пластины.

Sheet С_у
A1: Санузел — площади мокрой зоны
A2: Внутри с/у МДФ нет. Плитка стен и пола, ГВЛВ на потолок.
A4: Элемент | B4: Площадь, м² | C4: Запас, % | D4: К закупке, м² | E4: Материал
A5: Стены с/у внутри | B5: =SUMIF(Стены!C5:C18,"мокрый",Стены!F5:F18) | C5: 12 | D5: =B5*(1+C5/100) | E5: плитка настенная
A6: Пол с/у | B6: =Полы!B9 | C6: 12 | D6: =B6*(1+C6/100) | E6: керамогранит
A7: Потолок с/у | B7: =Потолки!D9 | C7: 10 | D7: =B7*(1+C7/100) | E7: ГВЛВ + краска
A8: Гидроизоляция стен+пол (высота 2.0 по периметру + пол) | B8: 19.75 | C8: 10 | D8: =B8*(1+C8/100) | E8: обмазочная + лента
A10: Душ 900×900 по плану, унитаз, раковина, стиральная машина. Канализация и вода — во вкладке сметы, раздел сантехника.

Sheet Прочее
A1: Прочее — проёмы, периметры, сводные площади
A2: Справочник для закупки. Окна и двери есть — площади только для вычета и периметров.
A4: Показатель | B4: Значение | C4: Ед. | D4: Источник | E4: Комментарий
A5: Пол отапливаемый | B5: =Комнаты!C11 | C5: м² | D5: Комнаты | E5: без террасы
A6: Потолок скатный весь | B6: =Комнаты!D11 | C6: м² | D6: Комнаты | E6: пол / cos25°
A7: Стены к отделке, все | B7: =Стены!F19 | C7: м² | D7: Стены | E7: проёмы вычтены
A8: Стены под МДФ | B8: =Стены!F20 | C8: м² | D8: Стены | E8: жилая зона
A9: Стены с/у под плитку | B9: =Стены!F21 | C9: м² | D9: Стены | E9: внутри мокрой
A10: МДФ стены + потолки | B10: =Обшивка!B7 | C10: м² | D10: Обшивка | E10: без запаса
A11: МДФ к закупке с запасом | B11: =Обшивка!F7 | C11: м² | D11: Обшивка | E11: 10% стены / 15% скаты
A12: Остекление окон | B12: =Окна!G15 | C12: м² | D12: Окна | E12: не покупать
A13: Светопрозрачные всего (окна+ДН-4) | B13: =Окна!G17 | C13: м² | D13: Окна | E13: не покупать
A14: Проёмы дверей | B14: =Двери!G9 | C14: м² | D14: Двери | E14: не покупать
A15: Тёплый пол, пластины к закупке | B15: =Теплый_пол!B12 | C15: шт | D15: Теплый_пол | E15: кратно 40
A16: Труба ТП 16 мм | B16: =Теплый_пол!B14 | C16: м | D16: Теплый_пол | E16: +10%
A17: Периметр жилых комнат (плинтус) | B17: =Обшивка!B14 | C17: м.п. | D17: Обшивка | E17: уже с запасом
A18: Терраса — исключена | B18: 9.12 | C18: м² | D18: чертёж | E18: не трогаем
A21: Что не считаем и почему: окна и двери установлены; наружные стены, пол и потолок уже утеплены и зашиты плёнкой; каркасы перегородок стоят; терраса вне объёма.
