Workbook
Name ITOGO_ZADANIE: Смета!F112
Name ITOGO_REZERV: Смета!F113
Name ITOGO_REC: Смета!F114
Name ITOGO_VSEGO: Смета!F115

Sheet Титул
B2: ЛОКАЛЬНАЯ СМЕТА · ТОЛЬКО РАБОТЫ
B6: Ремонт ванной комнаты и туалета
B7: Дом серии ЛГ-137 · раздельный санузел (сантехкабина)
B8: Подробный расчёт работ для заказчика · материалы в смету не входят
B10: Объект | D10: Ванная 1700×1500 мм, туалет 1200×820 мм, высота 2550 мм
B11: Серия дома | D11: ЛГ-137 (сантехкабина, дверные проёмы ≈ 570×1980 мм)
B12: Состав сметы | D12: Только работы. Сантехника, плитка, трубы, смеси — закупка заказчика
B13: Не входит | D13: Демонтаж плитки · потолок · стояки ХВС/ГВС · канализационный стояк
B14: Условия | D14: В квартире живут: ежедневный временный унитаз, вынос стиральной машины
B15: Ванна (новая) | D15: Из наливного камня, тяжёлая — подиум, занос 3–4 человека
B16: Срок работ | D16: 18 рабочих дней (ориентир, без учёта поставки материалов)
B17: Дата сметы | D17: 04.09.2026
B18: Срок действия | D18: 30 календарных дней
B19: НДС | D19: Не облагается / по статусу исполнителя — уточняется в договоре
B22: ОСНОВНОЙ ОБЪЁМ | D22: РЕКОМЕНДУЕМЫЕ | F22: ИТОГО С РЕКОМЕНДАЦИЯМИ
B23: 444 757 ₽ | D23: 36 200 ₽ | F23: 503 195 ₽
B24: разделы 1–7 | D24: раздел 8, по согласованию | F24: работы, без материалов
B26: Пятьсот три тысячи сто девяносто пять рублей 00 копеек
B28: Что делаем · и чего не делаем
B30: ВХОДИТ В РАБОТЫ | E30: НЕ ВХОДИТ
B31: 1. Демонтаж унитаза и ежедневный временный унитаз на период проживания | E31: 1. Демонтаж старой плитки — не закладывался
B32: 2. Вынос стиральной машины и чугунной ванны (узкий проём — резка при необходимости) | E32: 2. Потолок: натяжной, реечный, покраска — не входит
B33: 3. Срезка старой внутриквартирной разводки воды; стояки не трогаем | E33: 3. Стояки холодной и горячей воды — без замены и сварки
B34: 4. Коллекторы ХВС/ГВС, фильтры стандарт 10", редукторы давления | E34: 4. Канализационный стояк — без замены; только отвод к инсталляции
B35: 5. Полипропилен на раковину, унитаз, стиральную машину и ванну + водорозетки | E35: 5. Расширение дверных проёмов и новые двери — не входят
B36: 6. Инсталляция, переход с чугунного отвода на пластик без замены стояка | E36: 6. Материалы, сантехника, плитка, доставка и подъём на этаж — отдельно
B37: 7. Гидроизоляция пола и стен до уровня ванны, усиленная зона душа | E37: 7. Замена полотенцесушителя на стояке ГВС — не входит
B38: 8. Керамогранит на пол, плитка на стены, подбивка порогов и плитка под двери | E38: 8. Тёплый пол электрический — не входит (можно добавить)
B39: 9. Подиум и установка тяжёлой ванны из наливного камня, смесители, душ, раковина, унитаз | E39: 9. Дизайн-проект и согласование перепланировки — не входят
B42: Расценки — рынок Санкт-Петербурга, 2026, работы в стеснённых санузлах сантехкабины. Итог уточняется после замера. Смета не оферта.
B44: Заказчик ______________________ | E44: Исполнитель ______________________
B45: подпись / расшифровка | E45: подпись / расшифровка

Sheet Сводка
B1: СВОДКА ПО РАЗДЕЛАМ
B3: Суммы связаны формулами с листом «Смета». Меняете количество или цену там — сводка обновляется.
B5: № | C5: Раздел | D5: Сумма, ₽ | E5: Доля основного | F5: Статус
B6: 1 | C6: Организация работ в жилой квартире | D6: =Смета!F14 | E6: =IF(Смета!F112=0,0,Смета!F14/Смета!F112) | F6: входит в задание
B7: 2 | C7: Демонтаж и вынос (без сбивки плитки) | D7: =Смета!F28 | E7: =IF(Смета!F112=0,0,Смета!F28/Смета!F112) | F7: входит в задание
B8: 3 | C8: Водоснабжение: коллекторы, фильтры 10", редукторы, полипропилен, водорозетки | D8: =Смета!F43 | E8: =IF(Смета!F112=0,0,Смета!F43/Смета!F112) | F8: входит в задание
B9: 4 | C9: Канализация (без стояка) и инсталляция | D9: =Смета!F55 | E9: =IF(Смета!F112=0,0,Смета!F55/Смета!F112) | F9: входит в задание
B10: 5 | C10: Подготовка оснований и гидроизоляция | D10: =Смета!F66 | E10: =IF(Смета!F112=0,0,Смета!F66/Смета!F112) | F10: входит в задание
B11: 6 | C11: Пороги и облицовка (керамогранит / плитка) | D11: =Смета!F82 | E11: =IF(Смета!F112=0,0,Смета!F82/Смета!F112) | F11: входит в задание
B12: 7 | C12: Установка оборудования: ванна из наливного камня, смесители, душ, раковина, унитаз | D12: =Смета!F97 | E12: =IF(Смета!F112=0,0,Смета!F97/Смета!F112) | F12: входит в задание
B13: 8 | C13: Рекомендуемые работы (для законченного результата) | D13: =Смета!F109 | E13: — | F13: по согласованию
B15: Итого по заданию (1–7) | D15: =Смета!F112
B16: Резерв 5% | D16: =Смета!F113
B17: Рекомендуемые (8) | D17: =Смета!F114
B18: Ориентир срока: 18 рабочих дней. На время работ унитаз ставится каждый вечер. Чугунную ванну из проёма 57 см обычно выносят частями. Новую ванну из наливного камня заносят 3–4 человека, при необходимости — через окно.

Sheet Смета
A1: ЛОКАЛЬНАЯ СМЕТА НА РАБОТЫ
A2: Ванная и туалет · дом серии ЛГ-137 · проживание на объекте · потолок и стояки не входят · плитку не сбиваем
A3: Колонки D и E можно править — сумма в F пересчитается. Раздел 8 не входит в основной итог, пока его не включат в договор.
A5: Исходные объёмы: ванна 1.70×1.50 м (2.55 м²), туалет 1.20×0.82 м (0.98 м²), высота 2.55 м. Стены под плитку: ванна 15.19 м², туалет+короб 10.67 м². Расчёт — лист «Объёмы».
A7: № | B7: Наименование работ | C7: Ед. | D7: Кол-во | E7: Цена, ₽ | F7: Сумма, ₽ | G7: Примечание
A8: РАЗДЕЛ 1. ОРГАНИЗАЦИЯ РАБОТ В ЖИЛОЙ КВАРТИРЕ
A9: Квартира остаётся жилой. Унитаз каждое утро снимается для производства работ и каждый вечер ставится обратно.
A10: 1.1 | B10: Защита коридора, дверей и чистых помещений (плёнка, картон, малярная лента) | C10: компл. | D10: 1 | E10: 4500 | F10: =ROUND(D10*E10,0) | G10: На весь период ремонта
A11: 1.2 | B11: Организация рабочего места и ежедневная уборка зоны работ | C11: смена | D11: 18 | E11: 500 | F11: =ROUND(D11*E11,0) | G11: 18 рабочих дней
A12: 1.3 | B12: Временный унитаз: монтаж вечером и демонтаж утром (проживание на объекте) | C12: цикл | D12: 18 | E12: 1300 | F12: =ROUND(D12*E12,0) | G12: Цикл = вечер + утро. Унитаз заказчика или технический
A13: 1.4 | B13: Перекрытие внутриквартирных отводов, организация временного водоснабжения | C13: компл. | D13: 1 | E13: 2000 | F13: =ROUND(D13*E13,0) | G13: Стояки ХВС / ГВС не отключаем без необходимости
A14: Итого по разделу 1 | F14: =SUM(F10:F13)
A16: РАЗДЕЛ 2. ДЕМОНТАЖ И ВЫНОС (БЕЗ СБИВКИ ПЛИТКИ)
A17: Демонтаж плитки не выполняется. Потолок не затрагивается. Стояки воды и канализации сохраняются.
A18: 2.1 | B18: Демонтаж унитаза с сохранением выпуска канализации | C18: шт. | D18: 1 | E18: 2800 | F18: =ROUND(D18*E18,0) | G18: Аккуратно: чугунный раструб стояка не ломаем
A19: 2.2 | B19: Демонтаж раковины, смесителей, полок и навесных аксессуаров | C19: компл. | D19: 1 | E19: 2200 | F19: =ROUND(D19*E19,0)
A20: 2.3 | B20: Отключение и вынос стиральной машины из помещения | C20: шт. | D20: 1 | E20: 2500 | F20: =ROUND(D20*E20,0) | G20: Обратная установка — раздел 7
A21: 2.4 | B21: Демонтаж чугунной ванны (узкий проём 57 см, резка чаши при необходимости) | C21: шт. | D21: 1 | E21: 9000 | F21: =ROUND(D21*E21,0) | G21: Типично для ЛГ-137: ванна шире дверного проёма
A22: 2.5 | B22: Спуск и вынос чугунной ванны / частей из квартиры | C22: шт. | D22: 1 | E22: 7000 | F22: =ROUND(D22*E22,0) | G22: Лифт + вынос на контейнер / к машине заказчика
A23: 2.6 | B23: Срезка старых труб ХВС и ГВС внутриквартирной разводки | C23: компл. | D23: 1 | E23: 5000 | F23: =ROUND(D23*E23,0) | G23: Стояки не трогаем, отводы сохраняем для врезки
A24: 2.7 | B24: Демонтаж старых отводов канализации от ванны, раковины и стиральной машины | C24: компл. | D24: 1 | E24: 3500 | F24: =ROUND(D24*E24,0) | G24: Канализационный стояк не меняем
A25: 2.8 | B25: Извлечение деревянной закладной под унитаз и заделка полости | C25: шт. | D25: 1 | E25: 2800 | F25: =ROUND(D25*E25,0) | G25: Типовой узел ЛГ-137, доска обычно прогнившая
A26: 2.9 | B26: Подготовка плинтусов и примыканий у порогов (без работ по стоякам) | C26: компл. | D26: 1 | E26: 2500 | F26: =ROUND(D26*E26,0)
A27: 2.10 | B27: Сбор, мешкование, спуск и вынос строительного мусора | C27: компл. | D27: 1 | E27: 9000 | F27: =ROUND(D27*E27,0) | G27: Контейнер / утилизация — по факту, если требуется отдельно
A28: Итого по разделу 2 | F28: =SUM(F18:F27)
A30: РАЗДЕЛ 3. ВОДОСНАБЖЕНИЕ: КОЛЛЕКТОРЫ, ФИЛЬТРЫ 10", РЕДУКТОРЫ, ПОЛИПРОПИЛЕН, ВОДОРОЗЕТКИ
A31: Коллекторная схема. На ХВС и ГВС: фильтр стандарт 10" и редуктор давления. Стояки не перевариваются.
A32: 3.1 | B32: Сборка коллекторного узла ХВС (коллектор, фильтр стандарт 10", редуктор, краны) | C32: компл. | D32: 1 | E32: 9500 | F32: =ROUND(D32*E32,0) | G32: Материалы заказчика. Схема: кран → фильтр 10" → редуктор → коллектор
A33: 3.2 | B33: Сборка коллекторного узла ГВС (коллектор, фильтр стандарт 10", редуктор, краны) | C33: компл. | D33: 1 | E33: 9500 | F33: =ROUND(D33*E33,0) | G33: Аналогично ХВС
A34: 3.3 | B34: Обвязка существующих отводов со стояков: краны, счётчики, обратные клапаны | C34: компл. | D34: 1 | E34: 6000 | F34: =ROUND(D34*E34,0) | G34: Стояки и полотенцесушитель на стояке не меняем
A35: 3.4 | B35: Монтаж ревизионного шкафа / люка доступа к коллекторам и фильтрам | C35: шт. | D35: 1 | E35: 4000 | F35: =ROUND(D35*E35,0) | G35: Смена картриджей 10" без разбора короба
A36: 3.5 | B36: Прокладка труб полипропилен ХВС/ГВС до раковины, унитаза, стиральной машины и ванны | C36: м.п. | D36: 32 | E36: 850 | F36: =ROUND(D36*E36,0) | G36: Скрыто / в коробе. Пайка, крепление, теплоизоляция ГВС
A37: 3.6 | B37: Водорозетки под смеситель ванны (холодная + горячая), вывод в плоскость плитки | C37: компл. | D37: 1 | E37: 4200 | F37: =ROUND(D37*E37,0) | G37: 2 точки, жёсткая фиксация
A38: 3.7 | B38: Водорозетки под смеситель раковины (холодная + горячая) | C38: компл. | D38: 1 | E38: 4200 | F38: =ROUND(D38*E38,0) | G38: 2 точки
A39: 3.8 | B39: Водорозетка холодной воды под стиральную машину с отсечным краном | C39: шт. | D39: 1 | E39: 2500 | F39: =ROUND(D39*E39,0) | G39: 1 точка
A40: 3.9 | B40: Водорозетка холодной воды к инсталляции | C40: шт. | D40: 1 | E40: 2200 | F40: =ROUND(D40*E40,0) | G40: 1 точка
A41: 3.10 | B41: Штробление и проходы в стенах сантехкабины, заделка штраб | C41: м.п. | D41: 8 | E41: 900 | F41: =ROUND(D41*E41,0) | G41: Стены тонкие, армированные — работа аккуратная
A42: 3.11 | B42: Опрессовка системы водоснабжения и проверка соединений | C42: шт. | D42: 1 | E42: 4000 | F42: =ROUND(D42*E42,0) | G42: До закрытия коробов и до чистовой отделки
A43: Итого по разделу 3 | F43: =SUM(F32:F42)
A45: РАЗДЕЛ 4. КАНАЛИЗАЦИЯ (БЕЗ СТОЯКА) И ИНСТАЛЛЯЦИЯ
...

Sheet Объёмы
B1: РАСЧЁТ ОБЪЁМОВ · ТИПОВАЯ САНТЕХКАБИНА ЛГ-137
B3: Габариты приняты по типовой сантехкабине: ванна 1700×1500 мм, туалет 1200×820 мм, высота 2550 мм, двери 570×1980 мм. После замера объёмы на листе «Смета» правятся вручную.
B5: Параметр | C5: Формула / основание | D5: Значение | E5: Ед. | F5: Куда идёт | G5: Примечание
B6: Длина ванной | C6: типовой ЛГ-137 | D6: 1.7 | E6: м | F6: стены, пол | G6: макс. 1,73 м
B7: Ширина ванной | C7: типовой ЛГ-137 | D7: 1.5 | E7: м | F7: стены, пол | G7: ванна поперёк
B8: Длина туалета | C8: типовой ЛГ-137 | D8: 1.2 | E8: м | F8: стены, пол | G8: за унитазом вентшахта
B9: Ширина туалета | C9: типовой ЛГ-137 | D9: 0.82 | E9: м | F9: стены, пол | G9: 0,80–0,82 м
B10: Высота помещений | C10: сантехкабина | D10: 2.55 | E10: м | F10: стены | G10: потолок не входит в работы
B11: Дверной проём | C11: 2 шт. | D11: 0.57×1.98 | E11: м | F11: вычет из стен, пороги | G11: нестандарт 57 см
B12: Пол ванной | C12: 1,70 × 1,50 | D12: 2.55 | E12: м² | F12: п. 5.1–5.3, 6.4
B13: Пол туалета | C13: 1,20 × 0,82 | D13: 0.98 | E13: м² | F13: п. 5.1–5.3, 6.5
B14: Пол всего | C14: 2,55 + 0,98 | D14: 3.53 | E14: м² | F14: гидроизоляция, стяжка
B15: Стены ванной | C15: периметр × H − дверь | D15: 15.19 | E15: м² | F15: п. 5.4–5.5, 6.6 | G15: до существующего потолка
B16: Стены туалета | C16: периметр × H − дверь | D16: 9.17 | E16: м² | F16: п. 5.4–5.5
B17: Стены туалет + короб | C17: 9,17 + 1,50 | D17: 10.67 | E17: м² | F17: п. 6.7 | G17: плоскость инсталляции
B18: Гидроизоляция стен до ванны | C18: (P − дверь) × 0,70 | D18: 6.51 | E18: м² | F18: п. 5.6 | G18: ванная и туалет
B19: Зона душа над ванной | C19: (1,70+0,75) × 1,30 | D19: 3.19 | E19: м² | F19: п. 5.7 | G19: от 0,70 до 2,00 м
B20: Затирка | C20: пол + стены с коробом | D20: 29.39 | E20: м² | F20: п. 6.9
B21: Полипропилен ХВС+ГВС | C21: трасса коллектор → 4 прибора | D21: 32 | E21: м.п. | F21: п. 3.5 | G21: с запасом на подводы
B22: Канализация Ø50 | C22: ванна, раковина, стиралка | D22: 8 | E22: м.п. | F22: п. 4.1
B23: Канализация Ø110 | C23: выпуск стояка → инсталляция | D23: 1.5 | E23: м.п. | F23: п. 4.2 | G23: стояк не меняем
B24: Водорозетки | C24: ванна 2 + раковина 2 + СМ 1 + унитаз 1 | D24: 6 | E24: шт. | F24: п. 3.6–3.9
B25: Пороги | C25: два проёма | D25: 2 | E25: шт. | F25: п. 6.1–6.3, 6.8 | G25: подбивка + плитка под дверь
B26: Циклы временного унитаза | C26: вечерний монтаж + утренний демонтаж | D26: 18 | E26: цикл | F26: п. 1.3 | G26: пока нет чаши на инсталляции
B29: Точки водоразбора
B30: Прибор | C30: ХВС | D30: ГВС | E30: Канализация | F30: Водорозетки | G30: Комментарий
B31: Ванна + душ | C31: да | D31: да | E31: Ø50 | F31: 2 | G31: Смеситель настенный, душ над ванной
B32: Раковина | C32: да | D32: да | E32: Ø50 | F32: 2 | G32: Смеситель на раковину или настенный
B33: Стиральная машина | C33: да | D33: нет | E33: Ø50 | F33: 1 | G33: Кран на водорозетке
B34: Унитаз (инсталляция) | C34: да | D34: нет | E34: Ø110 | F34: 1 | G34: Подвод к раме, стояк не трогаем
B36: Схема коллектора (каждый стояк): отвод со стояка → шаровый кран → счётчик (существующий) → фильтр стандарт 10" → редуктор давления → обратный клапан → коллектор → отводы на точки. Стояк и полотенцесушитель на стояке ГВС не переделываем.

Sheet Условия
B1: СОСТАВ РАБОТ, ПОРЯДОК И УСЛОВИЯ ДЛЯ ЗАКАЗЧИКА
B4: 1. Как устроен объект
B5: Дом серии ЛГ-137, раздельный санузел — готовая сантехкабина: тонкие армированные стены, пол кабины ~50 мм, проёмы дверей около 570×1980 мм.
B6: Ванна стоит поперёк помещения 1700×1500 мм. Туалет 1200×820 мм: за унитазом стояки, канализация и вентшахта — места мало.
B7: Чугунный унитаз обычно зачеканен в раструб стояка и стоит на деревянной закладной в полу. Закладную при ремонте вынимаем и заделываем.
B9: 2. Что сознательно не делаем
B10: Не сбиваем плитку. Готовим существующее основание: грунт / бетоноконтакт и выравнивание под новую облицовку.
B11: Не трогаем потолок: нет демонтажа, покраски, натяжного или реечного потолка, потолочных светильников.
B12: Не меняем стояки холодной и горячей воды и канализационный стояк. Режем только внутриквартирную разводку от отводов.
B13: Не расширяем дверные проёмы и не ставим новые двери. Только порог: подбить и положить плитку под полотно.
B15: 3. Проживание во время ремонта
B16: Стиральную машину в первый день отключаем и выносим. После чистовых работ возвращаем и подключаем.
... B62: Скрытые работы фотофиксируем до закрытия. Опрессовка — до облицовки коробов.

Sheet Закупка заказчика
B1: ЧЕК-ЛИСТ ЗАКУПКИ ЗАКАЗЧИКА · В СМЕТУ РАБОТ НЕ ВХОДИТ
B3: Это не смета материалов и не цены. Список того, что нужно привезти на объект, чтобы бригада могла выполнить работы. Марку и модель выбираете вы (или вместе на замере).
B5: Код | C5: Позиция | D5: Количество / ориентир | E5: Для каких работ | F5: ✓
B6: ВОДА И КАНАЛИЗАЦИЯ
B7: К-01 | C7: Коллекторы ХВС и ГВС (по числу отводов, обычно 3+3 или 4+2) | D7: 2 шт. | E7: п. 3.1–3.2 | F7: ☐
B8: К-02 | C8: Фильтры стандарт 10" (корпус + картридж) на ХВС и ГВС | D8: 2 шт. | E8: п. 3.1–3.2 | F8: ☐
B9: К-03 | C9: Редукторы давления ХВС и ГВС | D9: 2 шт. | E9: п. 3.1–3.2 | F9: ☐
B10: К-04 | C10: Шаровые краны, американки, обратные клапаны, прокладки | D10: комплект | E10: п. 3.3 | F10: ☐
B11: К-05 | C11: Ревизионный шкаф / люк под коллекторы и фильтры | D11: 1 шт. | E11: п. 3.4 | F11: ☐
B12: К-06 | C12: Труба полипропилен PN20 + фитинги, клипсы, теплоизоляция ГВС | D12: ≈ 32 м + фитинги | E12: п. 3.5 | F12: ☐
B13: К-07 | C13: Водорозетки (внутренняя резьба 1/2") | D13: 6 шт. | E13: п. 3.6–3.9 | F13: ☐
B14: К-08 | C14: Кран угловой на стиральную машину | D14: 1 шт. | E14: п. 3.8 | F14: ☐
B15: К-09 | C15: Канализация ПВХ Ø50, Ø110, отводы, манжеты на чугун | D15: Ø50 ≈ 8 м, Ø110 ≈ 1,5 м | E15: п. 4.1–4.3 | F15: ☐
B17: ИНСТАЛЛЯЦИЯ И САНТЕХНИКА
B18: С-01 | C18: Инсталляция для подвесного унитаза + кнопка | D18: 1 компл. | E18: п. 4.4–4.8 | F18: ☐
B19: С-02 | C19: Унитаз подвесной совместимый с инсталляцией | D19: 1 шт. | E19: п. 7.9 | F19: ☐
B20: С-03 | C20: Ванна из наливного камня (проверить проход в проём 57 см / окно) | D20: 1 шт. | E20: п. 7.1–7.3 | F20: ☐
B21: С-04 | C21: Слив-перелив и сифон ванны под выбранную модель | D21: 1 шт. | E21: п. 7.4 | F21: ☐
B22: С-05 | C22: Смеситель на ванну | D22: 1 шт. | E22: п. 7.5 | F22: ☐
B23: С-06 | C23: Душевой комплект: стойка / лейка / шланг / держатель | D23: 1 шт. | E23: п. 7.6 | F23: ☐
B24: С-07 | C24: Раковина + крепёж + сифон | D24: 1 шт. | E24: п. 7.7 | F24: ☐
B25: С-08 | C25: Смеситель раковины | D25: 1 шт. | E25: п. 7.8 | F25: ☐
B26: С-09 | C26: Люк ревизии экрана ванны, люк кнопки инсталляции | D26: 2 шт. | E26: п. 4.7, 6.11 | F26: ☐
B27: С-10 | C27: Стеклянная шторка на ванну (если берёте п. 8.7) | D27: 1 шт. | E27: п. 8.7 | F27: ☐
B29: ОТДЕЛКА
B30: О-01 | C30: Грунт, бетоноконтакт, штукатурка / ровнитель стен | D30: по объёму стен 24 м² | E30: п. 5.4–5.5 | F30: ☐
B31: О-02 | C31: Смесь для стяжки пола | D31: ≈ 3,5 м² | E31: п. 5.2 | F31: ☐
B32: О-03 | C32: Обмазочная гидроизоляция + угловая лента + грунт к ней | D32: пол 3,5 м² + стены ~10 м² | E32: п. 5.3, 5.6–5.7 | F32: ☐
B33: О-04 | C33: Керамогранит на пол + запас 10–15% | D33: ≈ 4,1 м² с запасом | E33: п. 6.4–6.5, 6.8 | F33: ☐
B34: О-05 | C34: Плитка на стены + запас 10–15% | D34: ≈ 30 м² с запасом | E34: п. 6.6–6.7 | F34: ☐
B35: О-06 | C35: Клей для плитки, влагостойкая затирка, уголки / раскладки | D35: комплект | E35: п. 6.9–6.10 | F35: ☐
B36: О-07 | C36: Санитарный силикон в цвет затирки | D36: 2–3 тубы | E36: п. 6.12 | F36: ☐
B37: О-08 | C37: Влагостойкий ГВЛ, брусок / профиль на короб инсталляции | D37: ≈ 2,5 м² | E37: п. 4.6 | F37: ☐
B38: О-09 | C38: Блоки / клей на подиум и экран ванны | D38: по месту | E38: п. 6.11, 7.1 | F38: ☐
B40: ПРОЧЕЕ
B41: П-01 | C41: Временный унитаз (если нет запасного) + гофра | D41: 1 шт. на 18 дней | E41: п. 1.3 | F41: ☐
B42: П-02 | C42: Вентилятор в существующий канал (если берёте п. 8.2) | D42: 1 шт. | E42: п. 8.2 | F42: ☐
B43: П-03 | C43: Кабель, розетки IP44, УЗО / дифавтомат (если берёте п. 8.3–8.4) | D43: комплект | E43: п. 8.3–8.4 | F43: ☐
B44: П-04 | C44: Зеркало и аксессуары | D44: по выбору | E44: п. 8.5–8.6 | F44: ☐
B45: П-05 | C45: Мешки для мусора 120 л, плёнка, картон, скотч | D45: на период ремонта | E45: п. 1.1, 2.10 | F45: ☐
...
